2020-07-06 20:32:24,494 ERROR: Exception on /task_schedule [POST] [in C:\workspace\pythonWorkspace\ewms\venv\lib\site-packages\flask\app.py:1761]
Traceback (most recent call last):
  File "C:\workspace\pythonWorkspace\ewms\venv\lib\site-packages\sqlalchemy\engine\base.py", line 1179, in _execute_context
    context = constructor(dialect, self, conn, *args)
  File "C:\workspace\pythonWorkspace\ewms\venv\lib\site-packages\sqlalchemy\engine\default.py", line 719, in _init_compiled
    param.append(processors[key](compiled_params[key]))
  File "C:\workspace\pythonWorkspace\ewms\venv\lib\site-packages\sqlalchemy\dialects\sqlite\base.py", line 740, in process
    "SQLite DateTime type only accepts Python "
TypeError: SQLite DateTime type only accepts Python datetime and date objects as input.

The above exception was the direct cause of the following exception:

Traceback (most recent call last):
  File "C:\workspace\pythonWorkspace\ewms\venv\lib\site-packages\flask\app.py", line 2292, in wsgi_app
    response = self.full_dispatch_request()
  File "C:\workspace\pythonWorkspace\ewms\venv\lib\site-packages\flask\app.py", line 1815, in full_dispatch_request
    rv = self.handle_user_exception(e)
  File "C:\workspace\pythonWorkspace\ewms\venv\lib\site-packages\flask\app.py", line 1718, in handle_user_exception
    reraise(exc_type, exc_value, tb)
  File "C:\workspace\pythonWorkspace\ewms\venv\lib\site-packages\flask\_compat.py", line 35, in reraise
    raise value
  File "C:\workspace\pythonWorkspace\ewms\venv\lib\site-packages\flask\app.py", line 1813, in full_dispatch_request
    rv = self.dispatch_request()
  File "C:\workspace\pythonWorkspace\ewms\venv\lib\site-packages\flask\app.py", line 1799, in dispatch_request
    return self.view_functions[rule.endpoint](**req.view_args)
  File "C:\workspace\pythonWorkspace\workblog\app\routes.py", line 167, in task_schedule
    db.session.commit()
  File "C:\workspace\pythonWorkspace\ewms\venv\lib\site-packages\sqlalchemy\orm\scoping.py", line 162, in do
    return getattr(self.registry(), name)(*args, **kwargs)
  File "C:\workspace\pythonWorkspace\ewms\venv\lib\site-packages\sqlalchemy\orm\session.py", line 1026, in commit
    self.transaction.commit()
  File "C:\workspace\pythonWorkspace\ewms\venv\lib\site-packages\sqlalchemy\orm\session.py", line 493, in commit
    self._prepare_impl()
  File "C:\workspace\pythonWorkspace\ewms\venv\lib\site-packages\sqlalchemy\orm\session.py", line 472, in _prepare_impl
    self.session.flush()
  File "C:\workspace\pythonWorkspace\ewms\venv\lib\site-packages\sqlalchemy\orm\session.py", line 2451, in flush
    self._flush(objects)
  File "C:\workspace\pythonWorkspace\ewms\venv\lib\site-packages\sqlalchemy\orm\session.py", line 2589, in _flush
    transaction.rollback(_capture_exception=True)
  File "C:\workspace\pythonWorkspace\ewms\venv\lib\site-packages\sqlalchemy\util\langhelpers.py", line 68, in __exit__
    compat.reraise(exc_type, exc_value, exc_tb)
  File "C:\workspace\pythonWorkspace\ewms\venv\lib\site-packages\sqlalchemy\util\compat.py", line 129, in reraise
    raise value
  File "C:\workspace\pythonWorkspace\ewms\venv\lib\site-packages\sqlalchemy\orm\session.py", line 2549, in _flush
    flush_context.execute()
  File "C:\workspace\pythonWorkspace\ewms\venv\lib\site-packages\sqlalchemy\orm\unitofwork.py", line 422, in execute
    rec.execute(self)
  File "C:\workspace\pythonWorkspace\ewms\venv\lib\site-packages\sqlalchemy\orm\unitofwork.py", line 589, in execute
    uow,
  File "C:\workspace\pythonWorkspace\ewms\venv\lib\site-packages\sqlalchemy\orm\persistence.py", line 245, in save_obj
    insert,
  File "C:\workspace\pythonWorkspace\ewms\venv\lib\site-packages\sqlalchemy\orm\persistence.py", line 1120, in _emit_insert_statements
    statement, params
  File "C:\workspace\pythonWorkspace\ewms\venv\lib\site-packages\sqlalchemy\engine\base.py", line 988, in execute
    return meth(self, multiparams, params)
  File "C:\workspace\pythonWorkspace\ewms\venv\lib\site-packages\sqlalchemy\sql\elements.py", line 287, in _execute_on_connection
    return connection._execute_clauseelement(self, multiparams, params)
  File "C:\workspace\pythonWorkspace\ewms\venv\lib\site-packages\sqlalchemy\engine\base.py", line 1107, in _execute_clauseelement
    distilled_params,
  File "C:\workspace\pythonWorkspace\ewms\venv\lib\site-packages\sqlalchemy\engine\base.py", line 1182, in _execute_context
    e, util.text_type(statement), parameters, None, None
  File "C:\workspace\pythonWorkspace\ewms\venv\lib\site-packages\sqlalchemy\engine\base.py", line 1466, in _handle_dbapi_exception
    util.raise_from_cause(sqlalchemy_exception, exc_info)
  File "C:\workspace\pythonWorkspace\ewms\venv\lib\site-packages\sqlalchemy\util\compat.py", line 383, in raise_from_cause
    reraise(type(exception), exception, tb=exc_tb, cause=cause)
  File "C:\workspace\pythonWorkspace\ewms\venv\lib\site-packages\sqlalchemy\util\compat.py", line 128, in reraise
    raise value.with_traceback(tb)
  File "C:\workspace\pythonWorkspace\ewms\venv\lib\site-packages\sqlalchemy\engine\base.py", line 1179, in _execute_context
    context = constructor(dialect, self, conn, *args)
  File "C:\workspace\pythonWorkspace\ewms\venv\lib\site-packages\sqlalchemy\engine\default.py", line 719, in _init_compiled
    param.append(processors[key](compiled_params[key]))
  File "C:\workspace\pythonWorkspace\ewms\venv\lib\site-packages\sqlalchemy\dialects\sqlite\base.py", line 740, in process
    "SQLite DateTime type only accepts Python "
sqlalchemy.exc.StatementError: (builtins.TypeError) SQLite DateTime type only accepts Python datetime and date objects as input.
[SQL: INSERT INTO course (grade, name, start_date, end_date, start_time, end_time) VALUES (?, ?, ?, ?, ?, ?)]
[parameters: [{'start_time': '2020-01-01 12:01:23', 'end_time': '2020-01-01 12:01:23', 'grade': 1, 'start_date': '2020/07/04', 'end_date': '2020/08/29', 'name': 'ฟฦัง'}]]
